Workbook

Sheet Resumen
B2: Relación materias – simuladores CompanyGame
B3: Universidad del Valle (Univalle) · Facultad de Ciencias de la Administración y Fac. de Ciencias Sociales y Económicas
B4: Análisis del plan de estudios de cada pregrado frente al catálogo de simuladores CompanyGame
B6: Programa | C6: N.º de materias | D6: Encaje perfecto | E6: Encaje parcial | F6: No encaja / a desarrollar | G6: % con simulador CG
B7: Administración de Empresas | C7: =COUNTA('Administración de Empresas'!$B$3:$B$200) -> 61 | D7: =COUNTIF('Administración de Empresas'!$F$3:$F$200,"Encaje perfecto") -> 7 | E7: =COUNTIF('Administración de Empresas'!$F$3:$F$200,"Encaje parcial") -> 6 | F7: =COUNTIF('Administración de Empresas'!$F$3:$F$200,"No encaja") -> 47 | G7: =IFERROR((D7+E7)/C7,0) -> 0.21311475
B8: Contaduría Pública | C8: =COUNTA('Contaduría Pública'!$B$3:$B$200) -> 63 | D8: =COUNTIF('Contaduría Pública'!$F$3:$F$200,"Encaje perfecto") -> 3 | E8: =COUNTIF('Contaduría Pública'!$F$3:$F$200,"Encaje parcial") -> 4 | F8: =COUNTIF('Contaduría Pública'!$F$3:$F$200,"No encaja") -> 56 | G8: =IFERROR((D8+E8)/C8,0) -> 0.11111111
B9: Comercio Exterior | C9: =COUNTA('Comercio Exterior'!$B$3:$B$200) -> 49 | D9: =COUNTIF('Comercio Exterior'!$F$3:$F$200,"Encaje perfecto") -> 4 | E9: =COUNTIF('Comercio Exterior'!$F$3:$F$200,"Encaje parcial") -> 8 | F9: =COUNTIF('Comercio Exterior'!$F$3:$F$200,"No encaja") -> 37 | G9: =IFERROR((D9+E9)/C9,0) -> 0.24489796
B10: Finanzas y Banca | C10: =COUNTA('Finanzas y Banca'!$B$3:$B$200) -> 52 | D10: =COUNTIF('Finanzas y Banca'!$F$3:$F$200,"Encaje perfecto") -> 4 | E10: =COUNTIF('Finanzas y Banca'!$F$3:$F$200,"Encaje parcial") -> 4 | F10: =COUNTIF('Finanzas y Banca'!$F$3:$F$200,"No encaja") -> 44 | G10: =IFERROR((D10+E10)/C10,0) -> 0.15384615
B11: Economía | C11: =COUNTA(Economía!$B$3:$B$200) -> 50 | D11: =COUNTIF(Economía!$F$3:$F$200,"Encaje perfecto") -> 0 | E11: =COUNTIF(Economía!$F$3:$F$200,"Encaje parcial") -> 3 | F11: =COUNTIF(Economía!$F$3:$F$200,"No encaja") -> 47 | G11: =IFERROR((D11+E11)/C11,0) -> 0.06
B12: Gestión Emprend. e Innovación | C12: =COUNTA('Gestión Emprend. e Innovación'!$B$3:$B$200) -> 56 | D12: =COUNTIF('Gestión Emprend. e Innovación'!$F$3:$F$200,"Encaje perfecto") -> 6 | E12: =COUNTIF('Gestión Emprend. e Innovación'!$F$3:$F$200,"Encaje parcial") -> 9 | F12: =COUNTIF('Gestión Emprend. e Innovación'!$F$3:$F$200,"No encaja") -> 41 | G12: =IFERROR((D12+E12)/C12,0) -> 0.26785714
B13: Administración Turística | C13: =COUNTA('Administración Turística'!$B$3:$B$200) -> 50 | D13: =COUNTIF('Administración Turística'!$F$3:$F$200,"Encaje perfecto") -> 5 | E13: =COUNTIF('Administración Turística'!$F$3:$F$200,"Encaje parcial") -> 7 | F13: =COUNTIF('Administración Turística'!$F$3:$F$200,"No encaja") -> 38 | G13: =IFERROR((D13+E13)/C13,0) -> 0.24
B14: TOTAL | C14: =SUM(C7:C13) -> 381 | D14: =SUM(D7:D13) -> 29 | E14: =SUM(E7:E13) -> 41 | F14: =SUM(F7:F13) -> 310 | G14: =IFERROR((D14+E14)/C14,0) -> 0.18372703
B16: Convención de la columna 'Grado de ajuste':
B17: Encaje perfecto | C17: Un simulador CompanyGame cubre directamente la materia
B18: Encaje parcial | C18: Un simulador CG cubre parte de la materia; se sugiere complementar/desarrollar
B19: No encaja | C19: Ningún simulador CG aplica; se propone el tipo de simulador a desarrollar
B21: Notas metodológicas
B22: · La columna 'Semestre' corresponde al avance del plan de estudios de cada pregrado.
B23: · Pensums tomados de las estructuras curriculares oficiales de Univalle entregadas por la institución:
B24: Administración de Empresas (Res. 246/2020, 10 sem, 165 cr), Contaduría Pública (Res. 240/2020, 10 sem, 170 cr),
B25: Comercio Exterior (9 sem), Finanzas y Banca (9 sem, 150 cr), Economía (Res. 045/2020, 9 sem),
B26: Gestión del Emprendimiento y la Innovación (8 sem, 140 cr) y Administración Turística (9 sem).
B27: · Catálogo de simuladores tomado de companygame.com (8 categorías; ver hoja 'Catálogo CompanyGame').
B28: · Niveles CG: N1-2 Intro · N3-4 Avanzado · N5 Graduate · N6-7 Postgrado/Executive.
B29: · Administración Turística apalanca la línea HORECA; Finanzas y Banca la línea Finanzas y Banca (Bankgame/Trading/BankCompany);
B30: Economía es muy teórica-cuantitativa (bajo encaje directo).

Sheet Catálogo CompanyGame
A1: Catálogo de simuladores CompanyGame
A2: Fuente: companygame.com
A4: Categoría | B4: Simulador | C4: Nivel | D4: Descripción / área temática
A5: Negocios y Estrategia | B5: T-Shirt | C5: N1-2 | D5: Introducción a la gestión empresarial (sector textil)
A6: Negocios y Estrategia | B6: Sunny Day | C6: N1-2 | D6: Introducción a la gestión; visión global (bebidas/consumo)
A7: Negocios y Estrategia | B7: Energy&Co | C7: N1-2 | D7: Introducción a la gestión empresarial (sector energético)
A8: Negocios y Estrategia | B8: Business21 | C8: N3-4 | D8: Dirección general intermedia; visión integral
A9: Negocios y Estrategia | B9: Business Global | C9: N5 | D9: Dirección general avanzada; simulación gerencial integral
A10: Negocios y Estrategia | B10: Business Strategy | C10: N6-7 | D10: Estrategia empresarial (executive/posgrado)
A11: Marketing y Ventas | B11: MarketGame | C11: N1-2 | D11: Introducción al marketing y decisiones comerciales
A12: Marketing y Ventas | B12: Coffee Time | C12: N1-2 | D12: Marketing y retail (sector cafetería)
A13: Marketing y Ventas | B13: Food Company | C13: N3-4 | D13: Marketing estratégico sector alimentos
A14: Marketing y Ventas | B14: SalesManager | C14: N3-4 | D14: Gestión de la fuerza de ventas
A15: Marketing y Ventas | B15: TechCompany | C15: N5 | D15: Marketing sector tecnológico
... A45: Operaciones | B45: Milk Factory | C45: N5 | D45: Gestión de operaciones y producción (planta láctea)

Sheet Administración de Empresas
A1: Administración de Empresas · Universidad del Valle (Univalle)
A2: Semestre | B2: Materia | C2: Área temática | D2: Simulador CompanyGame que encaja | E2: Nivel CG | F2: Grado de ajuste | G2: Tipo de simulador a desarrollar (si no encaja / parcial) | H2: Observación
A3: 1 | B3: Fundamentos de Economía y Comercio | C3: Economía | D3: — | E3: — | F3: No encaja | G3: Simulador macro/microeconómico (economía de mercado y política económica)
A4: 1 | B4: Cálculo | C4: Cuantitativa | D4: — | E4: — | F4: No encaja | G4: Juego/simulador de aplicación matemática a decisiones de negocio
A5: 1 | B5: Introducción al Derecho y Constitución Política | C5: Jurídica | D5: — | E5: — | F5: No encaja | G5: Simulador jurídico-empresarial (casos y contratos)
A6: 1 | B6: Proceso Administrativo | C6: Administración | D6: T-Shirt / Sunny Day | E6: N1-2 | F6: Encaje perfecto
A7: 1 | B7: Taller Habilidades y Herramientas Informáticas para la Gestión | C7: Digital | D7: — | E7: — | F7: No encaja | G7: Simulador de ofimática, gestión de la información y competencias digitales
A8: 1 | B8: Fundamentos de Contabilidad | C8: Contabilidad | D8: ContaTrainer | E8: N1-2 | F8: Encaje perfecto
A9: 2 | B9: Álgebra Lineal | C9: Cuantitativa | D9: — | E9: — | F9: No encaja | G9: Juego/simulador de aplicación matemática a decisiones de negocio
A10: 2 | B10: Macroeconomía y Coyuntura | C10: Economía | D10: — | E10: — | F10: No encaja | G10: Simulador macro/microeconómico (economía de mercado y política económica)
A11: 2 | B11: Ciencias Humanas | C11: Humanidades | D11: — | E11: — | F11: No encaja | G11: Serious game de competencias humanísticas, ciudadanas y espirituales
A12: 2 | B12: Diseño Organizacional | C12: Administración | D12: — | E12: — | F12: No encaja
A13: 2 | B13: Pensamiento Clásico de la Administración y las Organizaciones | C13: Administración | D13: Business21 | E13: N3-4 | F13: Encaje parcial
A14: 2 | B14: Comprensión y Producción de textos académicos generales | C14: Comunicación | D14: — | E14: — | F14: No encaja | G14: Simulador de competencias comunicativas (comprensión y producción de textos)
A15: 2 | B15: Componente Vida Saludable | C15: Humanidades / Bienestar | D15: — | E15: — | F15: No encaja | G15: Serious game de competencias humanísticas, ciudadanas y espirituales
A16: 3 | B16: Estadística I para las ciencias de la administración | C16: Cuantitativa | D16: — | E16: — | F16: No encaja | G16: Simulador de análisis estadístico y decisiones basadas en datos
A17: 3 | B17: Pensamiento Contemporáneo de la Administración y las Organizaciones | C17: Administración | D17: — | E17: — | F17: No encaja
A18: 3 | B18: Organización y Sociedad | C18: Administración | D18: — | E18: — | F18: No encaja
A19: 3 | B19: Legislación Comercial | C19: Jurídica | D19: — | E19: — | F19: No encaja | G19: Simulador jurídico-empresarial (casos y contratos)
A20: 3 | B20: Matemática para finanzas | C20: Finanzas | D20: Advisor Jr. | E20: N1-2 / N3-4 | F20: Encaje parcial | G20: Simulador de matemática financiera (valor del dinero en el tiempo)
A21: 3 | B21: Economía de Empresa | C21: Economía | D21: — | E21: — | F21: No encaja | G21: Simulador macro/microeconómico (economía de mercado y política económica)
A22: 3 | B22: Inglés I | C22: Idiomas | D22: — | E22: — | F22: No encaja | G22: Simulador conversacional de idiomas / role-play de negocios en otro idioma (IA)
A23: 4 | B23: Estadística II para las ciencias de la administración | C23: Cuantitativa | D23: — | E23: — | F23: No encaja | G23: Simulador de análisis estadístico y decisiones basadas en datos
A24: 4 | B24: Modelos y Simulación de datos para las organizaciones | C24: Cuantitativa / Analítica | D24: — | E24: — | F24: No encaja | G24: Simulador de herramientas para la toma de decisiones (métodos analíticos)
A25: 4 | B25: Legislación laboral | C25: Jurídica | D25: — | E25: — | F25: No encaja | G25: Simulador jurídico-empresarial (casos y contratos)
A26: 4 | B26: Mercadeo | C26: Marketing | D26: Coffee Time | E26: N1-2 | F26: Encaje perfecto
A27: 4 | B27: Costos y Presupuestos Gerenciales | C27: Costos | D27: Corbatul | E27: N3-4 | F27: Encaje perfecto
A28: 4 | B28: Lectura Crítica | C28: Comunicación | D28: — | E28: — | F28: No encaja | G28: Simulador de competencias comunicativas (comprensión y producción de textos)
A29: 4 | B29: Inglés II | C29: Idiomas | E29: — | F29: No encaja | G29: Simulador conversacional de idiomas / role-play de negocios en otro idioma (IA)
A30: 5 | B30: Investigación y Gestión de Operaciones | C30: Operaciones | E30: — | F30: No encaja
A31: 5 | B31: Gestión del Conocimiento e Innovación | C31: Innovación / Gestión | E31: — | F31: No encaja
A32: 5 | B32: Humanismo, pensamiento administrativo y organizaciones | C32: Humanidades | D32: — | E32: — | F32: No encaja | G32: Serious game de competencias humanísticas, ciudadanas y espirituales
A33: 5 | B33: Investigación de Mercados | C33: Marketing | D33: FOCUS | E33: N5 | F33: Encaje perfecto
A34: 5 | B34: Análisis Integrado del Entorno | C34: Estrategia | D34: — | E34: — | F34: No encaja | G34: Simulador de prospectiva y escenarios estratégicos
A35: 5 | B35: Responsabilidad Social Empresarial y Sostenibilidad | C35: Sostenibilidad | D35: ESG Management | E35: N5 | F35: Encaje parcial | G35: Simulador de responsabilidad social y sostenibilidad
A36: 5 | B36: Inglés III | C36: Idiomas | D36: — | E36: — | F36: No encaja | G36: Simulador conversacional de idiomas / role-play de negocios en otro idioma (IA)
A37: 6 | B37: Gestión de Bienes y Servicios | C37: Operaciones | D37: Milk Factory | E37: N5 | F37: Encaje perfecto
A38: 6 | B38: Sistemas de Información Gerencial | C38: Digital / Gestión | D38: — | E38: — | F38: No encaja
A39: 6 | B39: Leadership | C39: Administración / Liderazgo | D39: — | E39: — | F39: No encaja | G39: Simulador de habilidades gerenciales y liderazgo
A40: 6 | B40: Creación e Introducción de Productos | C40: Marketing / Innovación | D40: — | E40: — | F40: No encaja
...

Sheet Contaduría Pública
A1: Contaduría Pública · Universidad del Valle (Univalle)
A2: Semestre | B2: Materia | C2: Área temática | D2: Simulador CompanyGame que encaja | E2: Nivel CG | F2: Grado de ajuste | G2: Tipo de simulador a desarrollar (si no encaja / parcial) | H2: Observación
A3: 1 | B3: Cálculo | C3: Cuantitativa | D3: — | E3: — | F3: No encaja | G3: Juego/simulador de aplicación matemática a decisiones de negocio
A4: 1 | B4: Introducción a la contaduría pública | C4: Contabilidad | D4: — | E4: — | F4: No encaja
A5: 1 | B5: Fundamentos de contabilidad | C5: Contabilidad | D5: ContaTrainer | E5: N1-2 | F5: Encaje perfecto
A6: 1 | B6: Taller de habilidades informáticas para la gestión | C6: Digital | D6: — | E6: — | F6: No encaja | G6: Simulador de ofimática, gestión de la información y competencias digitales
A7: 1 | B7: Introducción al derecho y constitución política | C7: Jurídica | D7: — | E7: — | F7: No encaja | G7: Simulador jurídico-empresarial (casos y contratos)
A8: 1 | B8: Estilos de vida saludable | C8: Humanidades / Bienestar | D8: — | E8: — | F8: No encaja | G8: Serious game de competencias humanísticas, ciudadanas y espirituales
A9: 2 | B9: Álgebra lineal | C9: Cuantitativa | D9: — | E9: — | F9: No encaja | G9: Juego/simulador de aplicación matemática a decisiones de negocio
A10: 2 | B10: Matemática para finanzas | C10: Finanzas | D10: Advisor Jr. | E10: N1-2 / N3-4 | F10: Encaje parcial | G10: Simulador de matemática financiera (valor del dinero en el tiempo)
A11: 2 | B11: Contabilidad de los recursos y obligaciones de corto plazo | C11: Contabilidad | D11: — | E11: — | F11: No encaja
A12: 2 | B12: Comprensión y producción de textos académicos generales | C12: Comunicación | D12: — | E12: — | F12: No encaja | G12: Simulador de competencias comunicativas (comprensión y producción de textos)
A13: 2 | B13: Legislación comercial I | C13: Jurídica | D13: — | E13: — | F13: No encaja | G13: Simulador jurídico-empresarial (casos y contratos)
A14: 2 | B14: Fundamentos de Economía y Comercio | C14: Economía | D14: — | E14: — | F14: No encaja | G14: Simulador macro/microeconómico (economía de mercado y política económica)
A15: 3 | B15: Estadística I para las ciencias de la administración | C15: Cuantitativa | D15: — | E15: — | F15: No encaja | G15: Simulador de análisis estadístico y decisiones basadas en datos
A16: 3 | B16: Proceso administrativo | C16: Administración | D16: T-Shirt / Sunny Day | E16: N1-2 | F16: Encaje perfecto
A17: 3 | B17: Contabilidad de los recursos y obligaciones de largo plazo y patrimonio | C17: Contabilidad | D17: — | E17: — | F17: No encaja
A18: 3 | B18: Legislación laboral | C18: Jurídica | D18: — | E18: — | F18: No encaja | G18: Simulador jurídico-empresarial (casos y contratos)
A19: 3 | B19: Legislación comercial II | C19: Jurídica | D19: — | E19: — | F19: No encaja | G19: Simulador jurídico-empresarial (casos y contratos)
A20: 3 | B20: Macroeconomía y coyuntura | C20: Economía | D20: — | E20: — | F20: No encaja | G20: Simulador macro/microeconómico (economía de mercado y política económica)
A21: 3 | B21: Inglés I | C21: Idiomas | D21: — | E21: — | F21: No encaja | G21: Simulador conversacional de idiomas / role-play de negocios en otro idioma (IA)
A22: 4 | B22: Estadística II para las ciencias de la administración | C22: Cuantitativa | D22: — | E22: — | F22: No encaja | G22: Simulador de análisis estadístico y decisiones basadas en datos
A23: 4 | B23: Investigación y gestión de operaciones | C23: Operaciones | D23: Milk Factory | E23: N5 | F23: Encaje parcial | G23: Simulador de herramientas para la toma de decisiones (métodos analíticos)
A24: 4 | B24: Informes financieros | C24: Contabilidad | D24: — | E24: — | F24: No encaja
A25: 4 | B25: Hacienda pública | C25: Sector Público | D25: — | E25: — | F25: No encaja | G25: Simulador de finanzas y presupuesto público
A26: 4 | B26: Economía de empresa | C26: Economía | D26: — | E26: — | F26: No encaja | G26: Simulador macro/microeconómico (economía de mercado y política económica)
A27: 4 | B27: Inglés II | C27: Idiomas | D27: — | E27: — | F27: No encaja | G27: Simulador conversacional de idiomas / role-play de negocios en otro idioma (IA)
A28: 4 | B28: Formación social y ciudadana | C28: Humanidades | D28: — | E28: — | F28: No encaja | G28: Simulador de participación ciudadana y responsabilidad social
A29: 5 | B29: Humanismo, pensamiento administrativo y organizaciones – cátedra | C29: Humanidades | D29: — | E29: — | F29: No encaja | G29: Serious game de competencias humanísticas, ciudadanas y espirituales
A30: 5 | B30: Fundamentos de control, auditoría y aseguramiento | C30: Auditoría | D30: — | E30: — | F30: No encaja | G30: Simulador de auditoría, aseguramiento y control
A31: 5 | B31: Contabilidades especiales I | C31: Contabilidad | D31: — | E31: — | F31: No encaja
A32: 5 | B32: Costos | C32: Costos | D32: — | E32: — | F32: No encaja | G32: Simulador de costeo (ABC / gestión estratégica de costos)
A33: 5 | B33: Ciencias humanas | C33: Humanidades | D33: — | E33: — | F33: No encaja | G33: Serious game de competencias humanísticas, ciudadanas y espirituales
A34: 5 | B34: Contabilidad pública | C34: Sector Público | D34: — | E34: — | F34: No encaja | G34: Simulador de finanzas y presupuesto público
A35: 5 | B35: Inglés III | C35: Idiomas | D35: — | E35: — | F35: No encaja | G35: Simulador conversacional de idiomas / role-play de negocios en otro idioma (IA)
A36: 6 | B36: Impuesto a la renta y complementarios, impuesto al patrimonio | C36: Tributaria | D36: — | E36: — | F36: No encaja | G36: Simulador tributario (liquidación de impuestos y planeación fiscal)
A37: 6 | B37: Auditoría, riesgos y aseguramiento | C37: Auditoría | D37: — | E37: — | F37: No encaja | G37: Simulador de auditoría, aseguramiento y control
A38: 6 | B38: Contabilidades especiales II | C38: Contabilidad | D38: — | E38: — | F38: No encaja
A39: 6 | B39: Presupuestos | C39: Costos / Finanzas | D39: Corbatul | E39: N3-4 | F39: Encaje perfecto | G39: Simulador de presupuestación empresarial
A40: 6 | B40: Seminario de teoría contable | C40: Contabilidad | D40: — | E40: — | F40: No encaja | G40: No aplica simulador (asignatura teórica/conceptual)
...

Sheet Comercio Exterior
A1: Comercio Exterior · Universidad del Valle (Univalle)
A2: Semestre | B2: Materia | C2: Área temática | D2: Simulador CompanyGame que encaja | E2: Nivel CG | F2: Grado de ajuste | G2: Tipo de simulador a desarrollar (si no encaja / parcial) | H2: Observación
A3: 1 | B3: Cálculo | C3: Cuantitativa | D3: — | E3: — | F3: No encaja | G3: Juego/simulador de aplicación matemática a decisiones de negocio
A4: 1 | B4: Fundamentos de Economía y Comercio | C4: Economía | D4: — | E4: — | F4: No encaja | G4: Simulador macro/microeconómico (economía de mercado y política económica)
A5: 1 | B5: Introducción al Derecho y Constitución Política | C5: Jurídica | D5: — | E5: — | F5: No encaja | G5: Simulador jurídico-empresarial (casos y contratos)
A6: 1 | B6: Proceso Administrativo | C6: Administración | D6: T-Shirt / Sunny Day | E6: N1-2 | F6: Encaje perfecto
A7: 1 | B7: Taller de Habilidades Informáticas para la Gestión | C7: Digital | D7: — | E7: — | F7: No encaja | G7: Simulador de ofimática, gestión de la información y competencias digitales
A8: 1 | B8: Fundamentos de Contabilidad | C8: Contabilidad | D8: ContaTrainer | E8: N1-2 | F8: Encaje perfecto
A9: 2 | B9: Álgebra Lineal | C9: Cuantitativa | D9: — | E9: — | F9: No encaja | G9: Juego/simulador de aplicación matemática a decisiones de negocio
A10: 2 | B10: Sistemas de Información Gerencial | C10: Digital / Gestión | D10: — | E10: — | F10: No encaja | G10: Simulador de sistemas de información contable/gerencial (ERP)
A11: 2 | B11: Legislación Comercial | C11: Jurídica | D11: — | E11: — | F11: No encaja | G11: Simulador jurídico-empresarial (casos y contratos)
A12: 2 | B12: Macroeconomía y Coyuntura | C12: Economía | D12: — | E12: — | F12: No encaja | G12: Simulador macro/microeconómico (economía de mercado y política económica)
A13: 2 | B13: Régimen Aduanero | C13: Comercio Exterior | D13: — | E13: — | F13: No encaja | G13: Simulador de comercio exterior, aduanas y medios de pago
A14: 2 | B14: Comprensión y Producción de Textos Académicos | C14: Comunicación | D14: — | E14: — | F14: No encaja | G14: Simulador de competencias comunicativas (comprensión y producción de textos)
A15: 2 | B15: Lenguas I | C15: Idiomas | D15: — | E15: — | F15: No encaja | G15: Simulador conversacional de idiomas / role-play de negocios en otro idioma (IA)
A16: 3 | B16: Estadística I para las Ciencias de la Administración | C16: Cuantitativa | D16: — | E16: — | F16: No encaja | G16: Simulador de análisis estadístico y decisiones basadas en datos
A17: 3 | B17: Matemática para Finanzas | C17: Finanzas | D17: Advisor Jr. | E17: N1-2 / N3-4 | F17: Encaje parcial | G17: Simulador de matemática financiera (valor del dinero en el tiempo)
A18: 3 | B18: Legislación Laboral | C18: Jurídica | D18: — | E18: — | F18: No encaja | G18: Simulador jurídico-empresarial (casos y contratos)
A19: 3 | B19: Economía de Empresa | C19: Economía | D19: — | E19: — | F19: No encaja | G19: Simulador macro/microeconómico (economía de mercado y política económica)
A20: 3 | B20: Importaciones | C20: Comercio Exterior | D20: — | E20: — | F20: No encaja
A21: 3 | B21: Lenguas II | C21: Idiomas | D21: — | E21: — | F21: No encaja | G21: Simulador conversacional de idiomas / role-play de negocios en otro idioma (IA)
A22: 4 | B22: Estadística II para las Ciencias de la Administración | C22: Cuantitativa | D22: — | E22: — | F22: No encaja | G22: Simulador de análisis estadístico y decisiones basadas en datos
A23: 4 | B23: Ciencias Humanas | C23: Humanidades | D23: — | E23: — | F23: No encaja | G23: Serious game de competencias humanísticas, ciudadanas y espirituales
A24: 4 | B24: Derecho Internacional Público y Privado | C24: Jurídica | D24: — | E24: — | F24: No encaja | G24: Simulador jurídico-empresarial (casos y contratos)
A25: 4 | B25: Teoría de Comercio Exterior | C25: Comercio Exterior | D25: Inter Pyme | E25: N3-4 | F25: Encaje parcial | G25: Simulador de comercio exterior, aduanas y medios de pago
A26: 4 | B26: Exportaciones | C26: Comercio Exterior | D26: Avocado Expand | E26: N3-4 | F26: Encaje parcial | G26: Simulador de comercio exterior, aduanas y medios de pago
A27: 4 | B27: Lenguas III | C27: Idiomas | D27: — | E27: — | F27: No encaja | G27: Simulador conversacional de idiomas / role-play de negocios en otro idioma (IA)
A28: 5 | B28: Humanismo, Pensamiento Administrativo y Organizaciones | C28: Humanidades | D28: — | E28: — | F28: No encaja | G28: Serious game de competencias humanísticas, ciudadanas y espirituales
A29: 5 | B29: Investigación y Gestión de Operaciones | C29: Operaciones | D29: — | E29: — | F29: No encaja
A30: 5 | B30: Régimen Cambiario | C30: Comercio Exterior / Finanzas | D30: — | E30: — | F30: No encaja | G30: Simulador de mercado cambiario, divisas y régimen cambiario (FOREX)
A31: 5 | B31: Mercadeo | C31: Marketing | D31: Coffee Time | E31: N1-2 | F31: Encaje perfecto
A32: 5 | B32: Técnicas de Negociación Internacional | C32: Negociación | D32: — | E32: — | F32: No encaja | G32: Simulador de negociación (role-play con contraparte)
A33: 5 | B33: Análisis de los Sistemas de Producción de Bienes y Servicios | C33: Operaciones | D33: Milk Factory | E33: N5 | F33: Encaje parcial | G33: Simulador de gestión de operaciones y producción
A34: 5 | B34: Lenguas IV | C34: Idiomas | D34: — | E34: — | F34: No encaja | G34: Simulador conversacional de idiomas / role-play de negocios en otro idioma (IA)
A35: 6 | B35: Análisis de Costos y Presupuestos | C35: Costos | D35: — | E35: — | F35: No encaja
A36: 6 | B36: Estrategias y Negocios Internacionales | C36: Estrategia / Global | D36: Global 2020 | E36: N6-7 | F36: Encaje parcial
A37: 6 | B37: Logística y Distribución Física Nacional e Internacional | C37: Logística | D37: — | E37: — | F37: No encaja | G37: Simulador de logística y cadena de suministro (DFI / supply chain)
A38: 6 | B38: Tratados y Acuerdos Comerciales | C38: Comercio Exterior | D38: Business Advance | E38: N5 | F38: Encaje parcial
A39: 6 | B39: Geoeconomía | C39: Economía / Global | D39: — | E39: — | F39: No encaja | G39: Simulador macro/microeconómico (economía de mercado y política económica)
A40: 7 | B40: Inteligencia de Negocios y Analítica de Datos para la Gestión | C40: Analítica / Digital | D40: — | E40: — | F40: No encaja | G40: Simulador de analítica de datos e inteligencia de negocios (BI)
...

Sheet Finanzas y Banca
A1: Finanzas y Banca · Universidad del Valle (Univalle)
A2: Semestre | B2: Materia | C2: Área temática | D2: Simulador CompanyGame que encaja | E2: Nivel CG | F2: Grado de ajuste | G2: Tipo de simulador a desarrollar (si no encaja / parcial) | H2: Observación
A3: 1 | B3: Matemática I | C3: Cuantitativa | D3: — | E3: — | F3: No encaja | G3: Juego/simulador de aplicación matemática a decisiones de negocio
A4: 1 | B4: Proceso administrativo | C4: Administración | D4: T-Shirt / Sunny Day | E4: N1-2 | F4: Encaje perfecto
A5: 1 | B5: Fundamentos contabilidad | C5: Contabilidad | D5: ContaTrainer | E5: N1-2 | F5: Encaje perfecto
A6: 1 | B6: Fundamentos economía y comercio | C6: Economía | D6: — | E6: — | F6: No encaja | G6: Simulador macro/microeconómico (economía de mercado y política económica)
A7: 1 | B7: Historia financiera y bancaria | C7: Finanzas / Banca | D7: — | E7: — | F7: No encaja | G7: No aplica simulador (asignatura teórica/conceptual)
A8: 1 | B8: Componente artístico humanístico | C8: Humanidades | D8: — | E8: — | F8: No encaja | G8: Serious game de competencias humanísticas, ciudadanas y espirituales
A9: 2 | B9: Matemática II | C9: Cuantitativa | D9: — | E9: — | F9: No encaja | G9: Juego/simulador de aplicación matemática a decisiones de negocio
A10: 2 | B10: Componente artístico humanístico | C10: Humanidades | D10: — | E10: — | F10: No encaja | G10: Serious game de competencias humanísticas, ciudadanas y espirituales
A11: 2 | B11: Contabilidad financiera | C11: Contabilidad | D11: — | E11: — | F11: No encaja
A12: 2 | B12: Sistemas de información financiera (TIC) | C12: Finanzas / Digital | D12: — | E12: — | F12: No encaja | G12: Simulador de sistemas de información contable/gerencial (ERP)
A13: 2 | B13: Introducción al derecho y la constitución política | C13: Jurídica | D13: — | E13: — | F13: No encaja | G13: Simulador jurídico-empresarial (casos y contratos)
A14: 2 | B14: Componente estilos de vida saludable | C14: Humanidades / Bienestar | D14: — | E14: — | F14: No encaja | G14: Serious game de competencias humanísticas, ciudadanas y espirituales
A15: 3 | B15: Estadística I | C15: Cuantitativa | D15: — | E15: — | F15: No encaja | G15: Simulador de análisis estadístico y decisiones basadas en datos
A16: 3 | B16: Lenguas I | C16: Idiomas | D16: — | E16: — | F16: No encaja | G16: Simulador conversacional de idiomas / role-play de negocios en otro idioma (IA)
A17: 3 | B17: Contabilidad de Instituciones Financieras I | C17: Finanzas / Banca | D17: — | E17: — | F17: No encaja
A18: 3 | B18: Macroeconomía | C18: Economía | D18: — | E18: — | F18: No encaja | G18: Simulador macro/microeconómico (economía de mercado y política económica)
A19: 3 | B19: Productos y servicios de mercados financieros | C19: Finanzas / Banca | D19: — | E19: — | F19: No encaja | G19: Simulador de banca y negocios financieros digitales
A20: 3 | B20: Componente científico tecnológico | C20: Digital | D20: — | E20: — | F20: No encaja | G20: Simulador de ofimática, gestión de la información y competencias digitales
A21: 4 | B21: Estadística II | C21: Cuantitativa | D21: — | E21: — | F21: No encaja | G21: Simulador de análisis estadístico y decisiones basadas en datos
A22: 4 | B22: Matemática financiera | C22: Finanzas | D22: Advisor Jr. | E22: N1-2 / N3-4 | F22: Encaje parcial | G22: Simulador de matemática financiera (valor del dinero en el tiempo)
A23: 4 | B23: Contabilidad de instituciones financieras II | C23: Finanzas / Banca | D23: Bankgame | E23: N5 | F23: Encaje parcial
A24: 4 | B24: Análisis financiero | C24: Finanzas | D24: — | E24: — | F24: No encaja
A25: 4 | B25: Lenguas II | C25: Idiomas | D25: — | E25: — | F25: No encaja | G25: Simulador conversacional de idiomas / role-play de negocios en otro idioma (IA)
A26: 4 | B26: Componente Lenguaje y comunicación | C26: Comunicación | D26: — | E26: — | F26: No encaja | G26: Simulador de competencias comunicativas (comprensión y producción de textos)
A27: 5 | B27: Formulación y evaluación de proyectos financieros | C27: Proyectos | D27: Fitness Gym | E27: N3-4 | F27: Encaje parcial | G27: Simulador de formulación y evaluación de proyectos (VPN/TIR)
A28: 5 | B28: Costos y presupuestos | C28: Costos | D28: Corbatul | E28: N3-4 | F28: Encaje perfecto | G28: Simulador de costeo (ABC / gestión estratégica de costos)
A29: 5 | B29: Administración financiera | C29: Finanzas | D29: — | E29: — | F29: No encaja
A30: 5 | B30: Econometría | C30: Economía / Cuantitativa | D30: — | E30: — | F30: No encaja | G30: Simulador de análisis estadístico y decisiones basadas en datos
A31: 5 | B31: Mercados financieros | C31: Finanzas / Banca | D31: Trading (Real Market Stocks) | E31: N3-4 | F31: Encaje perfecto
A32: 5 | B32: Electiva profesional I | C32: Electiva | D32: — | E32: — | F32: No encaja | G32: Depende de la electiva elegida (asignar simulador según su contenido)
A33: 5 | B33: Lenguas III | C33: Idiomas | D33: — | E33: — | F33: No encaja | G33: Simulador conversacional de idiomas / role-play de negocios en otro idioma (IA)
A34: 6 | B34: Metodología de la Investigación | C34: Investigación | D34: — | E34: — | F34: No encaja | G34: Simulador del proceso de investigación (diseño de estudios y metodología)
A35: 6 | B35: Control Interno y gobierno corporativo | C35: Auditoría / Estrategia | D35: — | E35: — | F35: No encaja | G35: Simulador de auditoría, aseguramiento y control
A36: 6 | B36: Contabilidad Pública | C36: Sector Público | D36: — | E36: — | F36: No encaja | G36: Simulador de finanzas y presupuesto público
A37: 6 | B37: Electiva Profesional II | C37: Electiva | D37: — | E37: — | F37: No encaja
A38: 6 | B38: Inversiones y Riesgos | C38: Finanzas / Riesgo | D38: — | E38: — | F38: No encaja
A39: 6 | B39: Lenguas IV | C39: Idiomas | D39: — | E39: — | F39: No encaja
A40: 7 | B40: Ética y desarrollo profesional | C40: Ética | D40: — | E40: — | F40: No encaja
...

Sheet Economía
A1: Economía · Universidad del Valle (Univalle)
A2: Semestre | B2: Materia | C2: Área temática | D2: Simulador CompanyGame que encaja | E2: Nivel CG | F2: Grado de ajuste | G2: Tipo de simulador a desarrollar (si no encaja / parcial) | H2: Observación
A3: 1 | B3: Principios de Economía | C3: Economía | D3: — | E3: — | F3: No encaja | G3: Simulador macro/microeconómico (economía de mercado y política económica)
A4: 1 | B4: Teoría Social | C4: Humanidades / Economía | D4: — | E4: — | F4: No encaja | G4: Serious game de competencias humanísticas, ciudadanas y espirituales
A5: 1 | B5: Matemática Básica | C5: Cuantitativa | D5: — | E5: — | F5: No encaja | G5: Juego/simulador de aplicación matemática a decisiones de negocio
A6: 1 | B6: Historia Económica General | C6: Economía | D6: — | E6: — | F6: No encaja | G6: Simulador macro/microeconómico (economía de mercado y política económica)
A7: 1 | B7: Comprensión y Producción de Textos Académicos Generales | C7: Comunicación | D7: — | E7: — | F7: No encaja | G7: Simulador de competencias comunicativas (comprensión y producción de textos)
A8: 1 | B8: Inglés I | C8: Idiomas | D8: — | E8: — | F8: No encaja | G8: Simulador conversacional de idiomas / role-play de negocios en otro idioma (IA)
A9: 2 | B9: Microeconomía I | C9: Economía | D9: — | E9: — | F9: No encaja | G9: Simulador macro/microeconómico (economía de mercado y política económica)
A10: 2 | B10: Filosofía Política | C10: Humanidades | D10: — | E10: — | F10: No encaja | G10: Serious game de competencias humanísticas, ciudadanas y espirituales
A11: 2 | B11: Cálculo I | C11: Cuantitativa | D11: — | E11: — | F11: No encaja | G11: Juego/simulador de aplicación matemática a decisiones de negocio
A12: 2 | B12: Álgebra Lineal | C12: Cuantitativa | D12: — | E12: — | F12: No encaja | G12: Juego/simulador de aplicación matemática a decisiones de negocio
A13: 2 | B13: Inglés II | C13: Idiomas | D13: — | E13: — | F13: No encaja | G13: Simulador conversacional de idiomas / role-play de negocios en otro idioma (IA)
A14: 2 | B14: Formación Social y Ciudadana | C14: Humanidades | D14: — | E14: — | F14: No encaja | G14: Simulador de participación ciudadana y responsabilidad social
... A52: 9 | B52: Electiva Profesional IV | C52: Electiva | D52: — | E52: — | F52: No encaja | G52: Depende de la electiva elegida (asignar simulador según su contenido)

Sheet Gestión Emprend. e Innovación
A1: Gestión Emprend. e Innovación · Universidad del Valle (Univalle)
A2: Semestre | B2: Materia | C2: Área temática | D2: Simulador CompanyGame que encaja | E2: Nivel CG | F2: Grado de ajuste | G2: Tipo de simulador a desarrollar (si no encaja / parcial) | H2: Observación
A3: 1 | B3: Creatividad e Innovación | C3: Innovación | D3: — | E3: — | F3: No encaja | G3: Simulador de creatividad, innovación y design thinking
A4: 1 | B4: Teorías y Modelos de Emprendimiento e Innovación | C4: Emprendimiento | D4: — | E4: — | F4: No encaja
A5: 1 | B5: Empresas y Empresarios (Investigación y Estudios de Caso) | C5: Emprendimiento | D5: — | E5: — | F5: No encaja
A6: 1 | B6: Ciencias Humanas | C6: Humanidades | D6: — | E6: — | F6: No encaja | G6: Serious game de competencias humanísticas, ciudadanas y espirituales
A7: 1 | B7: Formación Social y Ciudadana | C7: Humanidades | D7: — | E7: — | F7: No encaja | G7: Simulador de participación ciudadana y responsabilidad social
A8: 1 | B8: Fundamentos de Economía y Comercio | C8: Economía | D8: — | E8: — | F8: No encaja | G8: Simulador macro/microeconómico (economía de mercado y política económica)
A9: 1 | B9: Cálculo | C9: Cuantitativa | D9: — | E9: — | F9: No encaja | G9: Juego/simulador de aplicación matemática a decisiones de negocio
A10: 2 | B10: Liderazgo y Trabajo en Equipo | C10: Administración / Liderazgo | D10: — | E10: — | F10: No encaja | G10: Simulador de habilidades gerenciales y liderazgo
A11: 2 | B11: Mercadeo Estratégico | C11: Marketing | D11: — | E11: — | F11: No encaja
A12: 2 | B12: Legislación Comercial y Tributaria | C12: Jurídica / Tributaria | D12: — | E12: — | F12: No encaja | G12: Simulador tributario (liquidación de impuestos y planeación fiscal)
A13: 2 | B13: Científico Tecnológico | C13: Digital | D13: — | E13: — | F13: No encaja | G13: Simulador de ofimática, gestión de la información y competencias digitales
A14: 2 | B14: Análisis y Diagnóstico del Entorno | C14: Estrategia | D14: — | E14: — | F14: No encaja | G14: Simulador de prospectiva y escenarios estratégicos
A15: 2 | B15: Estadística para las Ciencias de la Administración | C15: Cuantitativa | D15: — | E15: — | F15: No encaja | G15: Simulador de análisis estadístico y decisiones basadas en datos
A16: 2 | B16: Fundamentos de Contabilidad | C16: Contabilidad | D16: ContaTrainer | E16: N1-2 | F16: Encaje perfecto
A17: 3 | B17: Ideación de Diseño de Nuevos Productos y Servicios | C17: Innovación / Marketing | D17: InnovaTech | E17: N3-4 | F17: Encaje parcial | G17: Simulador de creatividad, innovación y design thinking
A18: 3 | B18: Habilidades Gerenciales | C18: Administración / Liderazgo | D18: Energy & Co | E18: N2 | F18: Encaje parcial | G18: Simulador de habilidades gerenciales y liderazgo
A19: 3 | B19: Legislación Laboral | C19: Jurídica | D19: — | E19: — | F19: No encaja | G19: Simulador jurídico-empresarial (casos y contratos)
A20: 3 | B20: Inglés I | C20: Idiomas | D20: — | E20: — | F20: No encaja | G20: Simulador conversacional de idiomas / role-play de negocios en otro idioma (IA)
A21: 3 | B21: Comprensión y Producción de Textos Académicos Generales | C21: Comunicación | D21: — | E21: — | F21: No encaja | G21: Simulador de competencias comunicativas (comprensión y producción de textos)
A22: 3 | B22: Taller de Habilidades Informáticas para la Gestión | C22: Digital | D22: — | E22: — | F22: No encaja | G22: Simulador de ofimática, gestión de la información y competencias digitales
A23: 3 | B23: Matemáticas para Finanzas | C23: Finanzas | D23: Advisor Jr. | E23: N1-2 / N3-4 | F23: Encaje parcial | G23: Simulador de matemática financiera (valor del dinero en el tiempo)
A24: 4 | B24: Diseño y Gestión de Sistemas Productivos y Logísticos | C24: Operaciones / Logística | D24: — | E24: — | F24: No encaja | G24: Simulador de logística y cadena de suministro (DFI / supply chain)
A25: 4 | B25: Investigación de Mercados Estratégicos | C25: Marketing | D25: FOCUS | E25: N5 | F25: Encaje perfecto
A26: 4 | B26: Gestión Humana | C26: RR.HH. | D26: — | E26: — | F26: No encaja | G26: Simulador de gestión del talento humano (RR.HH.)
A27: 4 | B27: Humanismo, Pensamiento Administrativo y Organizaciones | C27: Humanidades | D27: — | E27: — | F27: No encaja | G27: Serious game de competencias humanísticas, ciudadanas y espirituales
A28: 4 | B28: Inglés II | C28: Idiomas | D28: — | E28: — | F28: No encaja | G28: Simulador conversacional de idiomas / role-play de negocios en otro idioma (IA)
A29: 4 | B29: Estilo de Vida Saludable | C29: Humanidades / Bienestar | D29: — | E29: — | F29: No encaja | G29: Serious game de competencias humanísticas, ciudadanas y espirituales
A30: 4 | B30: Análisis de Costos y Presupuestos | C30: Costos | D30: — | E30: — | F30: No encaja | G30: Simulador de costeo (ABC / gestión estratégica de costos)
A31: 5 | B31: Diseño de Nuevos Modelos de Negocios | C31: Emprendimiento / Innovación | D31: Business Chef | E31: N3-4 / N5 | F31: Encaje perfecto
A32: 5 | B32: Gestión del Cambio, Riesgo y la Incertidumbre | C32: Administración / Riesgo | D32: — | E32: — | F32: No encaja | G32: Simulador de gestión de riesgos y portafolios
A33: 5 | B33: Electiva Profesional I | C33: Electiva | D33: — | E33: — | F33: No encaja | G33: Depende de la electiva elegida (asignar simulador según su contenido)
A34: 5 | B34: Previsión y Prospectiva Estratégica | C34: Estrategia | D34: — | E34: — | F34: No encaja | G34: Simulador de prospectiva y escenarios estratégicos
A35: 5 | B35: Inglés III | C35: Idiomas | D35: — | E35: — | F35: No encaja | G35: Simulador conversacional de idiomas / role-play de negocios en otro idioma (IA)
A36: 5 | B36: Ética de los Negocios, Responsabilidad Social y Sostenibilidad Ambiental | C36: Sostenibilidad / Ética | D36: ESG Management | E36: N5 | F36: Encaje parcial | G36: Simulador de responsabilidad social y sostenibilidad
A37: 5 | B37: Red de Relaciones, Financiación e Inversión | C37: Finanzas / Emprendimiento | D37: — | E37: — | F37: No encaja
A38: 6 | B38: Laboratorio Empresarial Experiencial | C38: Emprendimiento / Simulación | D38: — | E38: — | F38: No encaja | H38: Laboratorio empresarial: encaje ideal
A39: 6 | B39: Electiva Profesional II | C39: Electiva | D39: — | E39: — | F39: No encaja | G39: Depende de la electiva elegida (asignar simulador según su contenido)
A40: 6 | B40: Derechos de Autor y Propiedad Intelectual | C40: Jurídica | D40: — | E40: — | F40: No encaja | G40: Simulador jurídico-empresarial (casos y contratos)
...

Sheet Administración Turística
A1: Administración Turística · Universidad del Valle (Univalle)
A2: Semestre | B2: Materia | C2: Área temática | D2: Simulador CompanyGame que encaja | E2: Nivel CG | F2: Grado de ajuste | G2: Tipo de simulador a desarrollar (si no encaja / parcial) | H2: Observación
A3: 1 | B3: Fundamentos de economía y comercio | C3: Economía | D3: — | E3: — | F3: No encaja | G3: Simulador macro/microeconómico (economía de mercado y política económica)
A4: 1 | B4: Cálculo | C4: Cuantitativa | D4: — | E4: — | F4: No encaja | G4: Juego/simulador de aplicación matemática a decisiones de negocio
A5: 1 | B5: Introducción al derecho y constitución política | C5: Jurídica | D5: — | E5: — | F5: No encaja | G5: Simulador jurídico-empresarial (casos y contratos)
A6: 1 | B6: Proceso administrativo | C6: Administración | D6: T-Shirt / Sunny Day | E6: N1-2 | F6: Encaje perfecto
A7: 1 | B7: Taller de habilidades informáticas para la gestión | C7: Digital | D7: — | E7: — | F7: No encaja | G7: Simulador de ofimática, gestión de la información y competencias digitales
A8: 1 | B8: Fundamentos de contabilidad | C8: Contabilidad | D8: ContaTrainer | E8: N1-2 | F8: Encaje perfecto
A9: 2 | B9: Comprensión y producción de textos académicos | C9: Comunicación | D9: — | E9: — | F9: No encaja | G9: Simulador de competencias comunicativas (comprensión y producción de textos)
A10: 2 | B10: Desarrollo turístico | C10: Turismo | D10: Hotel Virtual | E10: N1-2 | F10: Encaje parcial | G10: Simulador de planificación y gestión de destinos turísticos
A11: 2 | B11: Álgebra lineal | C11: Cuantitativa | D11: — | E11: — | F11: No encaja | G11: Juego/simulador de aplicación matemática a decisiones de negocio
A12: 2 | B12: Macroeconomía y coyuntura | C12: Economía | D12: — | E12: — | F12: No encaja | G12: Simulador macro/microeconómico (economía de mercado y política económica)
A13: 2 | B13: Contabilidad de costos para org. turísticas | C13: Costos | D13: — | E13: — | F13: No encaja | G13: Simulador de costeo (ABC / gestión estratégica de costos)
A14: 3 | B14: Inglés I | C14: Idiomas | D14: — | E14: — | F14: No encaja | G14: Simulador conversacional de idiomas / role-play de negocios en otro idioma (IA)
A15: 3 | B15: Geografía turística | C15: Turismo | D15: — | E15: — | F15: No encaja | G15: Simulador de planificación y gestión de destinos turísticos
A16: 3 | B16: Estadística I para ciencias de admón. | C16: Cuantitativa | D16: — | E16: — | F16: No encaja | G16: Simulador de análisis estadístico y decisiones basadas en datos
A17: 3 | B17: Economía de empresa | C17: Economía | D17: — | E17: — | F17: No encaja | G17: Simulador macro/microeconómico (economía de mercado y política económica)
A18: 3 | B18: Legislación laboral | C18: Jurídica | D18: — | E18: — | F18: No encaja | G18: Simulador jurídico-empresarial (casos y contratos)
A19: 3 | B19: Matemática para finanzas | C19: Finanzas | D19: Advisor Jr. | E19: N1-2 / N3-4 | F19: Encaje parcial | G19: Simulador de matemática financiera (valor del dinero en el tiempo)
A20: 4 | B20: Inglés II | C20: Idiomas | D20: — | E20: — | F20: No encaja | G20: Simulador conversacional de idiomas / role-play de negocios en otro idioma (IA)
... A22: 4 | B22: Patrimonio, cultura y turismo | C22: Turismo | D22: — | E22: — | F22: No encaja | G22: Simulador de planificación y gestión de destinos turísticos
A23: 4 | B23: Gestión de organizaciones gastronómicas | C23: HORECA / A&B | D23: Casa Guadalupe | E23: N3-4 | F23: Encaje perfecto
A24: 4 | B24: Ciencias humanas | C24: Humanidades | D24: — | E24: — | F24: No encaja | G24: Serious game de competencias humanísticas, ciudadanas y espirituales
A25: 4 | B25: Estadística II para ciencias de admón. | C25: Cuantitativa | D25: — | E25: — | F25: No encaja | G25: Simulador de análisis estadístico y decisiones basadas en datos
A26: 5 | B26: Inglés III | C26: Idiomas | D26: — | E26: — | F26: No encaja | G26: Simulador conversacional de idiomas / role-play de negocios en otro idioma (IA)
A27: 5 | B27: Español y comunicación | C27: Comunicación | D27: — | E27: — | F27: No encaja | G27: Simulador de competencias comunicativas (comprensión y producción de textos)
A28: 5 | B28: Ambiente, desarrollo sostenible y turismo | C28: Turismo / Sostenibilidad | D28: — | E28: — | F28: No encaja | G28: Simulador de gestión ambiental y sostenibilidad
A29: 5 | B29: Gestión del talento humano en org. turísticas | C29: RR.HH. | D29: — | E29: — | F29: No encaja | G29: Simulador de gestión del talento humano (RR.HH.)
A30: 5 | B30: Investigación y gestión de operaciones | C30: Operaciones | D30: Milk Factory | E30: N5 | F30: Encaje parcial | G30: Simulador de herramientas para la toma de decisiones (métodos analíticos)
A31: 6 | B31: Inglés IV | C31: Idiomas | D31: — | E31: — | F31: No encaja | G31: Simulador conversacional de idiomas / role-play de negocios en otro idioma (IA)
A32: 6 | B32: Gestión de establecimientos, tabernas y bares | C32: HORECA / A&B | D32: — | E32: — | F32: No encaja
A33: 6 | B33: Gestión de organizaciones de hospedaje | C33: Hotelería | D33: — | E33: — | F33: No encaja
A34: 6 | B34: Imagen de destino turístico | C34: Turismo / Marketing | D34: — | E34: — | F34: No encaja | G34: Simulador de planificación y gestión de destinos turísticos
A35: 6 | B35: Marketing de servicios | C35: Marketing / Servicios | D35: Five Stars | E35: N5 | F35: Encaje parcial | G35: Simulador de marketing de servicios
A36: 7 | B36: Español y comunicación II | C36: Comunicación | D36: — | E36: — | F36: No encaja | G36: Simulador de competencias comunicativas (comprensión y producción de textos)
A37: 7 | B37: Desarrollo de experiencias turísticas | C37: Turismo / Servicios | D37: — | E37: — | F37: No encaja | G37: Simulador de servicio al cliente y experiencia (CX)
A38: 7 | B38: Marketing electrónico para el turismo | C38: Marketing / Digital | D38: — | E38: — | F38: No encaja | G38: Simulador de marketing digital y e-commerce
A39: 7 | B39: Inteligencia de negocios y analítica para la gestión | C39: Analítica / Digital | D39: — | E39: — | F39: No encaja | G39: Simulador de analítica de datos e inteligencia de negocios (BI)
A40: 7 | B40: Administración y gestión financiera | C40: Finanzas | D40: Corbatul | E40: N3-4 | F40: Encaje perfecto
A41: 8 | B41: Servicio al cliente y relaciones públicas | C41: Servicios | D41: — | E41: — | F41: No encaja | G41: Simulador de servicio al cliente y experiencia (CX)
...
